[ERROR] 2025-06-12 19:29:06 - Erreur lors du chargement de la base de données: Expecting value: line 1 column 1 (char 0)
[ERROR] 2025-06-12 19:29:06 - [ERROR] Erreur lors de l'initialisation de la classe ollama : module 'config.settings' has no attribute 'KEY'
[ERROR] 2025-06-12 19:31:10 - Erreur lors du chargement de la base de données: Expecting value: line 1 column 1 (char 0)
[ERROR] 2025-06-12 19:31:11 - [ERROR] Erreur lors du chargement de la mémoire : Expecting value: line 1 column 1 (char 0)
[ERROR] 2025-06-12 19:31:11 - [ERROR] Erreur lors du chargement de la cog 'commands.admin.set' : Extension 'commands.admin.set' raised an error: ImportError: cannot import name 'REPORT_CHANNEL_ID' from 'config.settings' (D:\VisualStudio\Private Repository\pdl.bot Ai\config\settings.py)
Traceback (most recent call last):
  File "C:\Users\User\AppData\Local\Programs\Python\Python313\Lib\site-packages\discord\ext\commands\bot.py", line 951, in _load_from_module_spec
    spec.loader.exec_module(lib)  # type: ignore
    ~~~~~~~~~~~~~~~~~~~~~~~^^^^^
  File "<frozen importlib._bootstrap_external>", line 1026, in exec_module
  File "<frozen importlib._bootstrap>", line 488, in _call_with_frames_removed
  File "D:\VisualStudio\Private Repository\pdl.bot Ai\commands\admin\set.py", line 2, in <module>
    from config.settings import SECURITY_LOG_PATH, ERROR_LOG_PATH, REPORT_CHANNEL_ID
ImportError: cannot import name 'REPORT_CHANNEL_ID' from 'config.settings' (D:\VisualStudio\Private Repository\pdl.bot Ai\config\settings.py)

The above exception was the direct cause of the following exception:

Traceback (most recent call last):
  File "D:\VisualStudio\Private Repository\pdl.bot Ai\bot\bot.py", line 47, in load_cogs
    await bot.load_extension(cog)
  File "C:\Users\User\AppData\Local\Programs\Python\Python313\Lib\site-packages\discord\ext\commands\bot.py", line 1029, in load_extension
    await self._load_from_module_spec(spec, name)
  File "C:\Users\User\AppData\Local\Programs\Python\Python313\Lib\site-packages\discord\ext\commands\bot.py", line 954, in _load_from_module_spec
    raise errors.ExtensionFailed(key, e) from e
discord.ext.commands.errors.ExtensionFailed: Extension 'commands.admin.set' raised an error: ImportError: cannot import name 'REPORT_CHANNEL_ID' from 'config.settings' (D:\VisualStudio\Private Repository\pdl.bot Ai\config\settings.py)
[ERROR] 2025-06-12 19:31:11 - [ERROR] Erreur lors du chargement de la cog 'commands.admin.host' : Extension 'commands.admin.host' raised an error: SyntaxError: invalid syntax. Perhaps you forgot a comma? (host.py, line 35)
Traceback (most recent call last):
  File "C:\Users\User\AppData\Local\Programs\Python\Python313\Lib\site-packages\discord\ext\commands\bot.py", line 951, in _load_from_module_spec
    spec.loader.exec_module(lib)  # type: ignore
    ~~~~~~~~~~~~~~~~~~~~~~~^^^^^
  File "<frozen importlib._bootstrap_external>", line 1022, in exec_module
  File "<frozen importlib._bootstrap_external>", line 1160, in get_code
  File "<frozen importlib._bootstrap_external>", line 1090, in source_to_code
  File "<frozen importlib._bootstrap>", line 488, in _call_with_frames_removed
  File "D:\VisualStudio\Private Repository\pdl.bot Ai\commands\admin\host.py", line 35
    "⛔ Vous devez être administrateur du serveur pour utiliser cette commande.", ephemeral=True
                                                                                           ^^^^
SyntaxError: invalid syntax. Perhaps you forgot a comma?

The above exception was the direct cause of the following exception:

Traceback (most recent call last):
  File "D:\VisualStudio\Private Repository\pdl.bot Ai\bot\bot.py", line 47, in load_cogs
    await bot.load_extension(cog)
  File "C:\Users\User\AppData\Local\Programs\Python\Python313\Lib\site-packages\discord\ext\commands\bot.py", line 1029, in load_extension
    await self._load_from_module_spec(spec, name)
  File "C:\Users\User\AppData\Local\Programs\Python\Python313\Lib\site-packages\discord\ext\commands\bot.py", line 954, in _load_from_module_spec
    raise errors.ExtensionFailed(key, e) from e
discord.ext.commands.errors.ExtensionFailed: Extension 'commands.admin.host' raised an error: SyntaxError: invalid syntax. Perhaps you forgot a comma? (host.py, line 35)
[ERROR] 2025-06-12 19:31:11 - [ERROR] Erreur lors du chargement de la cog 'commands.public.help' : Extension 'commands.public.help' raised an error: SyntaxError: unterminated string literal (detected at line 39) (help.py, line 39)
Traceback (most recent call last):
  File "C:\Users\User\AppData\Local\Programs\Python\Python313\Lib\site-packages\discord\ext\commands\bot.py", line 951, in _load_from_module_spec
    spec.loader.exec_module(lib)  # type: ignore
    ~~~~~~~~~~~~~~~~~~~~~~~^^^^^
  File "<frozen importlib._bootstrap_external>", line 1022, in exec_module
  File "<frozen importlib._bootstrap_external>", line 1160, in get_code
  File "<frozen importlib._bootstrap_external>", line 1090, in source_to_code
  File "<frozen importlib._bootstrap>", line 488, in _call_with_frames_removed
  File "D:\VisualStudio\Private Repository\pdl.bot Ai\commands\public\help.py", line 39
    embed.add_field(name="/set channel <salon>", value="Définir les salons pris en charge. inline=False)
                                                       ^
SyntaxError: unterminated string literal (detected at line 39)

The above exception was the direct cause of the following exception:

Traceback (most recent call last):
  File "D:\VisualStudio\Private Repository\pdl.bot Ai\bot\bot.py", line 47, in load_cogs
    await bot.load_extension(cog)
  File "C:\Users\User\AppData\Local\Programs\Python\Python313\Lib\site-packages\discord\ext\commands\bot.py", line 1029, in load_extension
    await self._load_from_module_spec(spec, name)
  File "C:\Users\User\AppData\Local\Programs\Python\Python313\Lib\site-packages\discord\ext\commands\bot.py", line 954, in _load_from_module_spec
    raise errors.ExtensionFailed(key, e) from e
discord.ext.commands.errors.ExtensionFailed: Extension 'commands.public.help' raised an error: SyntaxError: unterminated string literal (detected at line 39) (help.py, line 39)
[ERROR] 2025-06-12 19:31:45 - [ERROR] Une erreur s'est produite lors du démarrage des tâches périodiques : 'function' object has no attribute 'is_running'
[ERROR] 2025-06-12 19:39:51 - Erreur lors du chargement de la base de données: Expecting value: line 1 column 1 (char 0)
[ERROR] 2025-06-12 19:39:52 - [ERROR] Erreur lors du chargement de la cog 'commands.admin.set' : Extension 'commands.admin.set' raised an error: ImportError: cannot import name 'REPORT_CHANNEL_ID' from 'config.settings' (D:\VisualStudio\Private Repository\pdl.bot Ai\config\settings.py)
Traceback (most recent call last):
  File "C:\Users\User\AppData\Local\Programs\Python\Python313\Lib\site-packages\discord\ext\commands\bot.py", line 951, in _load_from_module_spec
    spec.loader.exec_module(lib)  # type: ignore
    ~~~~~~~~~~~~~~~~~~~~~~~^^^^^
  File "<frozen importlib._bootstrap_external>", line 1026, in exec_module
  File "<frozen importlib._bootstrap>", line 488, in _call_with_frames_removed
  File "D:\VisualStudio\Private Repository\pdl.bot Ai\commands\admin\set.py", line 2, in <module>
    from config.settings import SECURITY_LOG_PATH, ERROR_LOG_PATH, REPORT_CHANNEL_ID
ImportError: cannot import name 'REPORT_CHANNEL_ID' from 'config.settings' (D:\VisualStudio\Private Repository\pdl.bot Ai\config\settings.py)

The above exception was the direct cause of the following exception:

Traceback (most recent call last):
  File "D:\VisualStudio\Private Repository\pdl.bot Ai\bot\bot.py", line 47, in load_cogs
    await bot.load_extension(cog)
  File "C:\Users\User\AppData\Local\Programs\Python\Python313\Lib\site-packages\discord\ext\commands\bot.py", line 1029, in load_extension
    await self._load_from_module_spec(spec, name)
  File "C:\Users\User\AppData\Local\Programs\Python\Python313\Lib\site-packages\discord\ext\commands\bot.py", line 954, in _load_from_module_spec
    raise errors.ExtensionFailed(key, e) from e
discord.ext.commands.errors.ExtensionFailed: Extension 'commands.admin.set' raised an error: ImportError: cannot import name 'REPORT_CHANNEL_ID' from 'config.settings' (D:\VisualStudio\Private Repository\pdl.bot Ai\config\settings.py)
[ERROR] 2025-06-12 19:39:52 - [ERROR] Erreur lors du chargement de la cog 'commands.admin.host' : Extension 'commands.admin.host' raised an error: SyntaxError: invalid syntax. Perhaps you forgot a comma? (host.py, line 35)
Traceback (most recent call last):
  File "C:\Users\User\AppData\Local\Programs\Python\Python313\Lib\site-packages\discord\ext\commands\bot.py", line 951, in _load_from_module_spec
    spec.loader.exec_module(lib)  # type: ignore
    ~~~~~~~~~~~~~~~~~~~~~~~^^^^^
  File "<frozen importlib._bootstrap_external>", line 1022, in exec_module
  File "<frozen importlib._bootstrap_external>", line 1160, in get_code
  File "<frozen importlib._bootstrap_external>", line 1090, in source_to_code
  File "<frozen importlib._bootstrap>", line 488, in _call_with_frames_removed
  File "D:\VisualStudio\Private Repository\pdl.bot Ai\commands\admin\host.py", line 35
    "⛔ Vous devez être administrateur du serveur pour utiliser cette commande.", ephemeral=True
                                                                                           ^^^^
SyntaxError: invalid syntax. Perhaps you forgot a comma?

The above exception was the direct cause of the following exception:

Traceback (most recent call last):
  File "D:\VisualStudio\Private Repository\pdl.bot Ai\bot\bot.py", line 47, in load_cogs
    await bot.load_extension(cog)
  File "C:\Users\User\AppData\Local\Programs\Python\Python313\Lib\site-packages\discord\ext\commands\bot.py", line 1029, in load_extension
    await self._load_from_module_spec(spec, name)
  File "C:\Users\User\AppData\Local\Programs\Python\Python313\Lib\site-packages\discord\ext\commands\bot.py", line 954, in _load_from_module_spec
    raise errors.ExtensionFailed(key, e) from e
discord.ext.commands.errors.ExtensionFailed: Extension 'commands.admin.host' raised an error: SyntaxError: invalid syntax. Perhaps you forgot a comma? (host.py, line 35)
[ERROR] 2025-06-12 19:39:52 - [ERROR] Erreur lors du chargement de la cog 'commands.public.help' : Extension 'commands.public.help' raised an error: SyntaxError: unterminated string literal (detected at line 39) (help.py, line 39)
Traceback (most recent call last):
  File "C:\Users\User\AppData\Local\Programs\Python\Python313\Lib\site-packages\discord\ext\commands\bot.py", line 951, in _load_from_module_spec
    spec.loader.exec_module(lib)  # type: ignore
    ~~~~~~~~~~~~~~~~~~~~~~~^^^^^
  File "<frozen importlib._bootstrap_external>", line 1022, in exec_module
  File "<frozen importlib._bootstrap_external>", line 1160, in get_code
  File "<frozen importlib._bootstrap_external>", line 1090, in source_to_code
  File "<frozen importlib._bootstrap>", line 488, in _call_with_frames_removed
  File "D:\VisualStudio\Private Repository\pdl.bot Ai\commands\public\help.py", line 39
    embed.add_field(name="/set channel <salon>", value="Définir les salons pris en charge. inline=False)
                                                       ^
SyntaxError: unterminated string literal (detected at line 39)

The above exception was the direct cause of the following exception:

Traceback (most recent call last):
  File "D:\VisualStudio\Private Repository\pdl.bot Ai\bot\bot.py", line 47, in load_cogs
    await bot.load_extension(cog)
  File "C:\Users\User\AppData\Local\Programs\Python\Python313\Lib\site-packages\discord\ext\commands\bot.py", line 1029, in load_extension
    await self._load_from_module_spec(spec, name)
  File "C:\Users\User\AppData\Local\Programs\Python\Python313\Lib\site-packages\discord\ext\commands\bot.py", line 954, in _load_from_module_spec
    raise errors.ExtensionFailed(key, e) from e
discord.ext.commands.errors.ExtensionFailed: Extension 'commands.public.help' raised an error: SyntaxError: unterminated string literal (detected at line 39) (help.py, line 39)
[ERROR] 2025-06-12 19:40:25 - [ERROR] Une erreur s'est produite lors du démarrage des tâches périodiques : 'function' object has no attribute 'is_running'
[ERROR] 2025-06-12 19:40:53 - Erreur lors du chargement de la base de données: Expecting value: line 1 column 1 (char 0)
[ERROR] 2025-06-12 19:40:54 - [ERROR] Erreur lors du chargement de la cog 'commands.admin.set' : Extension 'commands.admin.set' raised an error: ModuleNotFoundError: No module named 'home.plugin'
Traceback (most recent call last):
  File "C:\Users\User\AppData\Local\Programs\Python\Python313\Lib\site-packages\discord\ext\commands\bot.py", line 951, in _load_from_module_spec
    spec.loader.exec_module(lib)  # type: ignore
    ~~~~~~~~~~~~~~~~~~~~~~~^^^^^
  File "<frozen importlib._bootstrap_external>", line 1026, in exec_module
  File "<frozen importlib._bootstrap>", line 488, in _call_with_frames_removed
  File "D:\VisualStudio\Private Repository\pdl.bot Ai\commands\admin\set.py", line 6, in <module>
    from home.plugin.pipeline import set_whitelisted_channel
ModuleNotFoundError: No module named 'home.plugin'

The above exception was the direct cause of the following exception:

Traceback (most recent call last):
  File "D:\VisualStudio\Private Repository\pdl.bot Ai\bot\bot.py", line 47, in load_cogs
    await bot.load_extension(cog)
  File "C:\Users\User\AppData\Local\Programs\Python\Python313\Lib\site-packages\discord\ext\commands\bot.py", line 1029, in load_extension
    await self._load_from_module_spec(spec, name)
  File "C:\Users\User\AppData\Local\Programs\Python\Python313\Lib\site-packages\discord\ext\commands\bot.py", line 954, in _load_from_module_spec
    raise errors.ExtensionFailed(key, e) from e
discord.ext.commands.errors.ExtensionFailed: Extension 'commands.admin.set' raised an error: ModuleNotFoundError: No module named 'home.plugin'
[ERROR] 2025-06-12 19:40:54 - [ERROR] Erreur lors du chargement de la cog 'commands.admin.host' : Extension 'commands.admin.host' raised an error: SyntaxError: invalid syntax. Perhaps you forgot a comma? (host.py, line 35)
Traceback (most recent call last):
  File "C:\Users\User\AppData\Local\Programs\Python\Python313\Lib\site-packages\discord\ext\commands\bot.py", line 951, in _load_from_module_spec
    spec.loader.exec_module(lib)  # type: ignore
    ~~~~~~~~~~~~~~~~~~~~~~~^^^^^
  File "<frozen importlib._bootstrap_external>", line 1022, in exec_module
  File "<frozen importlib._bootstrap_external>", line 1160, in get_code
  File "<frozen importlib._bootstrap_external>", line 1090, in source_to_code
  File "<frozen importlib._bootstrap>", line 488, in _call_with_frames_removed
  File "D:\VisualStudio\Private Repository\pdl.bot Ai\commands\admin\host.py", line 35
    "⛔ Vous devez être administrateur du serveur pour utiliser cette commande.", ephemeral=True
                                                                                           ^^^^
SyntaxError: invalid syntax. Perhaps you forgot a comma?

The above exception was the direct cause of the following exception:

Traceback (most recent call last):
  File "D:\VisualStudio\Private Repository\pdl.bot Ai\bot\bot.py", line 47, in load_cogs
    await bot.load_extension(cog)
  File "C:\Users\User\AppData\Local\Programs\Python\Python313\Lib\site-packages\discord\ext\commands\bot.py", line 1029, in load_extension
    await self._load_from_module_spec(spec, name)
  File "C:\Users\User\AppData\Local\Programs\Python\Python313\Lib\site-packages\discord\ext\commands\bot.py", line 954, in _load_from_module_spec
    raise errors.ExtensionFailed(key, e) from e
discord.ext.commands.errors.ExtensionFailed: Extension 'commands.admin.host' raised an error: SyntaxError: invalid syntax. Perhaps you forgot a comma? (host.py, line 35)
[ERROR] 2025-06-12 19:40:54 - [ERROR] Erreur lors du chargement de la cog 'commands.public.help' : Extension 'commands.public.help' raised an error: SyntaxError: unterminated string literal (detected at line 39) (help.py, line 39)
Traceback (most recent call last):
  File "C:\Users\User\AppData\Local\Programs\Python\Python313\Lib\site-packages\discord\ext\commands\bot.py", line 951, in _load_from_module_spec
    spec.loader.exec_module(lib)  # type: ignore
    ~~~~~~~~~~~~~~~~~~~~~~~^^^^^
  File "<frozen importlib._bootstrap_external>", line 1022, in exec_module
  File "<frozen importlib._bootstrap_external>", line 1160, in get_code
  File "<frozen importlib._bootstrap_external>", line 1090, in source_to_code
  File "<frozen importlib._bootstrap>", line 488, in _call_with_frames_removed
  File "D:\VisualStudio\Private Repository\pdl.bot Ai\commands\public\help.py", line 39
    embed.add_field(name="/set channel <salon>", value="Définir les salons pris en charge. inline=False)
                                                       ^
SyntaxError: unterminated string literal (detected at line 39)

The above exception was the direct cause of the following exception:

Traceback (most recent call last):
  File "D:\VisualStudio\Private Repository\pdl.bot Ai\bot\bot.py", line 47, in load_cogs
    await bot.load_extension(cog)
  File "C:\Users\User\AppData\Local\Programs\Python\Python313\Lib\site-packages\discord\ext\commands\bot.py", line 1029, in load_extension
    await self._load_from_module_spec(spec, name)
  File "C:\Users\User\AppData\Local\Programs\Python\Python313\Lib\site-packages\discord\ext\commands\bot.py", line 954, in _load_from_module_spec
    raise errors.ExtensionFailed(key, e) from e
discord.ext.commands.errors.ExtensionFailed: Extension 'commands.public.help' raised an error: SyntaxError: unterminated string literal (detected at line 39) (help.py, line 39)
[ERROR] 2025-06-12 19:41:27 - [ERROR] Une erreur s'est produite lors du démarrage des tâches périodiques : 'function' object has no attribute 'is_running'
[ERROR] 2025-06-12 19:43:24 - Erreur lors du chargement de la base de données: Expecting value: line 1 column 1 (char 0)
[ERROR] 2025-06-12 19:43:26 - [ERROR] Erreur lors du chargement de la cog 'commands.admin.set' : Extension 'commands.admin.set' raised an error: NameError: name 'settings' is not defined
Traceback (most recent call last):
  File "C:\Users\User\AppData\Local\Programs\Python\Python313\Lib\site-packages\discord\ext\commands\bot.py", line 951, in _load_from_module_spec
    spec.loader.exec_module(lib)  # type: ignore
    ~~~~~~~~~~~~~~~~~~~~~~~^^^^^
  File "<frozen importlib._bootstrap_external>", line 1026, in exec_module
  File "<frozen importlib._bootstrap>", line 488, in _call_with_frames_removed
  File "D:\VisualStudio\Private Repository\pdl.bot Ai\commands\admin\set.py", line 8, in <module>
    db = Database(settings.SERVER_DB)
                  ^^^^^^^^
NameError: name 'settings' is not defined

The above exception was the direct cause of the following exception:

Traceback (most recent call last):
  File "D:\VisualStudio\Private Repository\pdl.bot Ai\bot\bot.py", line 47, in load_cogs
    await bot.load_extension(cog)
  File "C:\Users\User\AppData\Local\Programs\Python\Python313\Lib\site-packages\discord\ext\commands\bot.py", line 1029, in load_extension
    await self._load_from_module_spec(spec, name)
  File "C:\Users\User\AppData\Local\Programs\Python\Python313\Lib\site-packages\discord\ext\commands\bot.py", line 954, in _load_from_module_spec
    raise errors.ExtensionFailed(key, e) from e
discord.ext.commands.errors.ExtensionFailed: Extension 'commands.admin.set' raised an error: NameError: name 'settings' is not defined
[ERROR] 2025-06-12 19:44:03 - Erreur lors du chargement de la base de données: Expecting value: line 1 column 1 (char 0)
[ERROR] 2025-06-12 19:44:04 - Erreur lors du chargement de la base de données: Expecting value: line 1 column 1 (char 0)
[ERROR] 2025-06-12 19:44:38 - [ERROR] Une erreur s'est produite lors du démarrage des tâches périodiques : 'function' object has no attribute 'is_running'
[ERROR] 2025-06-12 19:48:01 - [ERROR] Une erreur s'est produite lors du démarrage des tâches périodiques : 'function' object has no attribute 'is_running'
[ERROR] 2025-06-12 19:48:12 - [ERROR] Erreur lors de la recherche de la réponse : Error code: 403 - {'error': {'message': 'Access denied. Please check your network settings.'}}
[ERROR] 2025-06-12 19:48:36 - [HOST] Erreur lors de l'affichage de l'hôte pour nythique (1233020939898327092): name 'bot_user' is not defined
Traceback (most recent call last):
  File "D:\VisualStudio\Private Repository\pdl.bot Ai\commands\admin\host.py", line 52, in host
    invite_url = f"https://discord.com/oauth2/authorize?client_id={bot_user.id}&scope=bot&permissions=8"
                                                                   ^^^^^^^^
NameError: name 'bot_user' is not defined
[ERROR] 2025-06-12 19:49:29 - [ERROR] Erreur lors de la recherche de la réponse : Error code: 403 - {'error': {'message': 'Access denied. Please check your network settings.'}}
[ERROR] 2025-06-12 19:54:27 - [ERROR] Une erreur s'est produite lors du démarrage des tâches périodiques : 'function' object has no attribute 'is_running'
[ERROR] 2025-06-12 19:54:47 - [ERROR] Erreur lors de la recherche de la réponse : Error code: 403 - {'error': {'message': 'Access denied. Please check your network settings.'}}
[ERROR] 2025-06-12 19:55:13 - [ERROR] Erreur lors de la recherche de la réponse : Error code: 403 - {'error': {'message': 'Access denied. Please check your network settings.'}}
[ERROR] 2025-06-12 19:55:53 - [ERROR] Erreur lors de la recherche de la réponse : Error code: 403 - {'error': {'message': 'Access denied. Please check your network settings.'}}
[ERROR] 2025-06-12 19:58:33 - [ERROR] Une erreur s'est produite lors du démarrage des tâches périodiques : 'function' object has no attribute 'is_running'
[ERROR] 2025-06-12 19:58:55 - [ERROR] Erreur lors de la recherche de la réponse : Error code: 403 - {'error': {'message': 'Access denied. Please check your network settings.'}}
[ERROR] 2025-06-12 20:04:37 - [STATUS] Erreur lors de la définition du statut du bot par nythique (1233020939898327092) : 'Database' object has no attribute 'update_bot_status'
Traceback (most recent call last):
  File "D:\VisualStudio\Private Repository\pdl.bot Ai\commands\admin\set.py", line 108, in status
    status = db.update_bot_status(message)
             ^^^^^^^^^^^^^^^^^^^^
AttributeError: 'Database' object has no attribute 'update_bot_status'. Did you mean: 'update_bot_stats'?
[ERROR] 2025-06-12 20:04:42 - Ignoring exception in command 'status'
Traceback (most recent call last):
  File "D:\VisualStudio\Private Repository\pdl.bot Ai\commands\admin\set.py", line 108, in status
    status = db.update_bot_status(message)
             ^^^^^^^^^^^^^^^^^^^^
AttributeError: 'Database' object has no attribute 'update_bot_status'. Did you mean: 'update_bot_stats'?

During handling of the above exception, another exception occurred:

Traceback (most recent call last):
  File "C:\Users\User\AppData\Local\Programs\Python\Python313\Lib\site-packages\discord\app_commands\commands.py", line 857, in _do_call
    return await self._callback(self.binding, interaction, **params)  # type: ignore
           ^^^^^^^^^^^^^^^^^^^^^^^^^^^^^^^^^^^^^^^^^^^^^^^^^^^^^^^^^
  File "D:\VisualStudio\Private Repository\pdl.bot Ai\commands\admin\set.py", line 118, in status
    await interaction.followup.send(embed=embed, ephemeral=True)
  File "C:\Users\User\AppData\Local\Programs\Python\Python313\Lib\site-packages\discord\webhook\async_.py", line 1857, in send
    data = await adapter.execute_webhook(
           ^^^^^^^^^^^^^^^^^^^^^^^^^^^^^^
    ...<11 lines>...
    )
    ^
  File "C:\Users\User\AppData\Local\Programs\Python\Python313\Lib\site-packages\discord\webhook\async_.py", line 224, in request
    raise NotFound(response, data)
discord.errors.NotFound: 404 Not Found (error code: 10015): Unknown Webhook

The above exception was the direct cause of the following exception:

Traceback (most recent call last):
  File "C:\Users\User\AppData\Local\Programs\Python\Python313\Lib\site-packages\discord\app_commands\tree.py", line 1310, in _call
    await command._invoke_with_namespace(interaction, namespace)
  File "C:\Users\User\AppData\Local\Programs\Python\Python313\Lib\site-packages\discord\app_commands\commands.py", line 883, in _invoke_with_namespace
    return await self._do_call(interaction, transformed_values)
           ^^^^^^^^^^^^^^^^^^^^^^^^^^^^^^^^^^^^^^^^^^^^^^^^^^^^
  File "C:\Users\User\AppData\Local\Programs\Python\Python313\Lib\site-packages\discord\app_commands\commands.py", line 876, in _do_call
    raise CommandInvokeError(self, e) from e
discord.app_commands.errors.CommandInvokeError: Command 'status' raised an exception: NotFound: 404 Not Found (error code: 10015): Unknown Webhook
[ERROR] 2025-06-12 20:05:34 - [HOST] Erreur lors de l'affichage de l'hôte pour nythique (1233020939898327092): name 'bot_user' is not defined
Traceback (most recent call last):
  File "D:\VisualStudio\Private Repository\pdl.bot Ai\commands\admin\host.py", line 52, in host
    invite_url = f"https://discord.com/oauth2/authorize?client_id={bot_user.id}&scope=bot&permissions=8"
                                                                   ^^^^^^^^
NameError: name 'bot_user' is not defined
[ERROR] 2025-06-12 20:07:58 - [ERROR] Une erreur s'est produite lors du démarrage des tâches périodiques : 'function' object has no attribute 'is_running'
[ERROR] 2025-06-12 20:19:46 - [ERROR] Une erreur s'est produite lors du démarrage des tâches périodiques : 'function' object has no attribute 'is_running'
[ERROR] 2025-06-12 20:24:05 - [ERROR] Une erreur s'est produite lors du démarrage de la tâche de changement de statut : 'function' object has no attribute 'is_running'
[ERROR] 2025-06-12 20:41:26 - [ERROR] Erreur lors du chargement de la cog 'commands.admin.set' : Extension 'commands.admin.set' raised an error: ImportError: cannot import name 'ROOT_USER' from 'config.settings' (D:\VisualStudio\Private Repository\pdl.bot Ai\config\settings.py)
Traceback (most recent call last):
  File "C:\Users\User\AppData\Local\Programs\Python\Python313\Lib\site-packages\discord\ext\commands\bot.py", line 951, in _load_from_module_spec
    spec.loader.exec_module(lib)  # type: ignore
    ~~~~~~~~~~~~~~~~~~~~~~~^^^^^
  File "<frozen importlib._bootstrap_external>", line 1026, in exec_module
  File "<frozen importlib._bootstrap>", line 488, in _call_with_frames_removed
  File "D:\VisualStudio\Private Repository\pdl.bot Ai\commands\admin\set.py", line 3, in <module>
    from config.settings import SECURITY_LOG_PATH, ERROR_LOG_PATH, ROOT_USER
ImportError: cannot import name 'ROOT_USER' from 'config.settings' (D:\VisualStudio\Private Repository\pdl.bot Ai\config\settings.py)

The above exception was the direct cause of the following exception:

Traceback (most recent call last):
  File "D:\VisualStudio\Private Repository\pdl.bot Ai\bot\bot.py", line 47, in load_cogs
    await bot.load_extension(cog)
  File "C:\Users\User\AppData\Local\Programs\Python\Python313\Lib\site-packages\discord\ext\commands\bot.py", line 1029, in load_extension
    await self._load_from_module_spec(spec, name)
  File "C:\Users\User\AppData\Local\Programs\Python\Python313\Lib\site-packages\discord\ext\commands\bot.py", line 954, in _load_from_module_spec
    raise errors.ExtensionFailed(key, e) from e
discord.ext.commands.errors.ExtensionFailed: Extension 'commands.admin.set' raised an error: ImportError: cannot import name 'ROOT_USER' from 'config.settings' (D:\VisualStudio\Private Repository\pdl.bot Ai\config\settings.py)
[ERROR] 2025-06-12 20:42:27 - [ERROR] Erreur lors du chargement de la cog 'commands.admin.debug' : Extension 'commands.admin.debug' raised an error: ImportError: cannot import name 'ROOT_UER' from 'config.settings' (D:\VisualStudio\Private Repository\pdl.bot Ai\config\settings.py)
Traceback (most recent call last):
  File "C:\Users\User\AppData\Local\Programs\Python\Python313\Lib\site-packages\discord\ext\commands\bot.py", line 951, in _load_from_module_spec
    spec.loader.exec_module(lib)  # type: ignore
    ~~~~~~~~~~~~~~~~~~~~~~~^^^^^
  File "<frozen importlib._bootstrap_external>", line 1026, in exec_module
  File "<frozen importlib._bootstrap>", line 488, in _call_with_frames_removed
  File "D:\VisualStudio\Private Repository\pdl.bot Ai\commands\admin\debug.py", line 5, in <module>
    from config.settings import ERROR_LOG_PATH, ROOT_UER
ImportError: cannot import name 'ROOT_UER' from 'config.settings' (D:\VisualStudio\Private Repository\pdl.bot Ai\config\settings.py)

The above exception was the direct cause of the following exception:

Traceback (most recent call last):
  File "D:\VisualStudio\Private Repository\pdl.bot Ai\bot\bot.py", line 47, in load_cogs
    await bot.load_extension(cog)
  File "C:\Users\User\AppData\Local\Programs\Python\Python313\Lib\site-packages\discord\ext\commands\bot.py", line 1029, in load_extension
    await self._load_from_module_spec(spec, name)
  File "C:\Users\User\AppData\Local\Programs\Python\Python313\Lib\site-packages\discord\ext\commands\bot.py", line 954, in _load_from_module_spec
    raise errors.ExtensionFailed(key, e) from e
discord.ext.commands.errors.ExtensionFailed: Extension 'commands.admin.debug' raised an error: ImportError: cannot import name 'ROOT_UER' from 'config.settings' (D:\VisualStudio\Private Repository\pdl.bot Ai\config\settings.py)
[ERROR] 2025-06-12 20:42:27 - [ERROR] Erreur lors du chargement de la cog 'commands.admin.restart' : Extension 'commands.admin.restart' raised an error: ImportError: cannot import name 'ROOT_UER' from 'config.settings' (D:\VisualStudio\Private Repository\pdl.bot Ai\config\settings.py)
Traceback (most recent call last):
  File "C:\Users\User\AppData\Local\Programs\Python\Python313\Lib\site-packages\discord\ext\commands\bot.py", line 951, in _load_from_module_spec
    spec.loader.exec_module(lib)  # type: ignore
    ~~~~~~~~~~~~~~~~~~~~~~~^^^^^
  File "<frozen importlib._bootstrap_external>", line 1026, in exec_module
  File "<frozen importlib._bootstrap>", line 488, in _call_with_frames_removed
  File "D:\VisualStudio\Private Repository\pdl.bot Ai\commands\admin\restart.py", line 4, in <module>
    from config.settings import SECURITY_LOG_PATH, ERROR_LOG_PATH, ROOT_UER
ImportError: cannot import name 'ROOT_UER' from 'config.settings' (D:\VisualStudio\Private Repository\pdl.bot Ai\config\settings.py)

The above exception was the direct cause of the following exception:

Traceback (most recent call last):
  File "D:\VisualStudio\Private Repository\pdl.bot Ai\bot\bot.py", line 47, in load_cogs
    await bot.load_extension(cog)
  File "C:\Users\User\AppData\Local\Programs\Python\Python313\Lib\site-packages\discord\ext\commands\bot.py", line 1029, in load_extension
    await self._load_from_module_spec(spec, name)
  File "C:\Users\User\AppData\Local\Programs\Python\Python313\Lib\site-packages\discord\ext\commands\bot.py", line 954, in _load_from_module_spec
    raise errors.ExtensionFailed(key, e) from e
discord.ext.commands.errors.ExtensionFailed: Extension 'commands.admin.restart' raised an error: ImportError: cannot import name 'ROOT_UER' from 'config.settings' (D:\VisualStudio\Private Repository\pdl.bot Ai\config\settings.py)
[ERROR] 2025-06-12 20:42:28 - [ERROR] Erreur lors du chargement de la cog 'commands.admin.host' : Extension 'commands.admin.host' raised an error: ImportError: cannot import name 'ROOT_UER' from 'config.settings' (D:\VisualStudio\Private Repository\pdl.bot Ai\config\settings.py)
Traceback (most recent call last):
  File "C:\Users\User\AppData\Local\Programs\Python\Python313\Lib\site-packages\discord\ext\commands\bot.py", line 951, in _load_from_module_spec
    spec.loader.exec_module(lib)  # type: ignore
    ~~~~~~~~~~~~~~~~~~~~~~~^^^^^
  File "<frozen importlib._bootstrap_external>", line 1026, in exec_module
  File "<frozen importlib._bootstrap>", line 488, in _call_with_frames_removed
  File "D:\VisualStudio\Private Repository\pdl.bot Ai\commands\admin\host.py", line 3, in <module>
    from config.settings import SECURITY_LOG_PATH, ERROR_LOG_PATH, ROOT_UER
ImportError: cannot import name 'ROOT_UER' from 'config.settings' (D:\VisualStudio\Private Repository\pdl.bot Ai\config\settings.py)

The above exception was the direct cause of the following exception:

Traceback (most recent call last):
  File "D:\VisualStudio\Private Repository\pdl.bot Ai\bot\bot.py", line 47, in load_cogs
    await bot.load_extension(cog)
  File "C:\Users\User\AppData\Local\Programs\Python\Python313\Lib\site-packages\discord\ext\commands\bot.py", line 1029, in load_extension
    await self._load_from_module_spec(spec, name)
  File "C:\Users\User\AppData\Local\Programs\Python\Python313\Lib\site-packages\discord\ext\commands\bot.py", line 954, in _load_from_module_spec
    raise errors.ExtensionFailed(key, e) from e
discord.ext.commands.errors.ExtensionFailed: Extension 'commands.admin.host' raised an error: ImportError: cannot import name 'ROOT_UER' from 'config.settings' (D:\VisualStudio\Private Repository\pdl.bot Ai\config\settings.py)
[ERROR] 2025-06-12 20:42:28 - [ERROR] Erreur lors du chargement de la cog 'commands.admin.empty' : Extension 'commands.admin.empty' raised an error: ImportError: cannot import name 'ROOT_UER' from 'config.settings' (D:\VisualStudio\Private Repository\pdl.bot Ai\config\settings.py)
Traceback (most recent call last):
  File "C:\Users\User\AppData\Local\Programs\Python\Python313\Lib\site-packages\discord\ext\commands\bot.py", line 951, in _load_from_module_spec
    spec.loader.exec_module(lib)  # type: ignore
    ~~~~~~~~~~~~~~~~~~~~~~~^^^^^
  File "<frozen importlib._bootstrap_external>", line 1026, in exec_module
  File "<frozen importlib._bootstrap>", line 488, in _call_with_frames_removed
  File "D:\VisualStudio\Private Repository\pdl.bot Ai\commands\admin\empty.py", line 4, in <module>
    from config.settings import SECURITY_LOG_PATH, ERROR_LOG_PATH, ROOT_UER
ImportError: cannot import name 'ROOT_UER' from 'config.settings' (D:\VisualStudio\Private Repository\pdl.bot Ai\config\settings.py)

The above exception was the direct cause of the following exception:

Traceback (most recent call last):
  File "D:\VisualStudio\Private Repository\pdl.bot Ai\bot\bot.py", line 47, in load_cogs
    await bot.load_extension(cog)
  File "C:\Users\User\AppData\Local\Programs\Python\Python313\Lib\site-packages\discord\ext\commands\bot.py", line 1029, in load_extension
    await self._load_from_module_spec(spec, name)
  File "C:\Users\User\AppData\Local\Programs\Python\Python313\Lib\site-packages\discord\ext\commands\bot.py", line 954, in _load_from_module_spec
    raise errors.ExtensionFailed(key, e) from e
discord.ext.commands.errors.ExtensionFailed: Extension 'commands.admin.empty' raised an error: ImportError: cannot import name 'ROOT_UER' from 'config.settings' (D:\VisualStudio\Private Repository\pdl.bot Ai\config\settings.py)
[ERROR] 2025-06-12 20:43:01 - [ERROR] Une erreur s'est produite lors du démarrage de la tâche de changement de statut : 'function' object has no attribute 'is_running'
[ERROR] 2025-06-12 20:43:46 - [ERROR] Erreur lors du chargement de la cog 'commands.admin.host' : Extension 'commands.admin.host' raised an error: ImportError: cannot import name 'ROOT_UER' from 'config.settings' (D:\VisualStudio\Private Repository\pdl.bot Ai\config\settings.py)
Traceback (most recent call last):
  File "C:\Users\User\AppData\Local\Programs\Python\Python313\Lib\site-packages\discord\ext\commands\bot.py", line 951, in _load_from_module_spec
    spec.loader.exec_module(lib)  # type: ignore
    ~~~~~~~~~~~~~~~~~~~~~~~^^^^^
  File "<frozen importlib._bootstrap_external>", line 1026, in exec_module
  File "<frozen importlib._bootstrap>", line 488, in _call_with_frames_removed
  File "D:\VisualStudio\Private Repository\pdl.bot Ai\commands\admin\host.py", line 3, in <module>
    from config.settings import SECURITY_LOG_PATH, ERROR_LOG_PATH, ROOT_UER
ImportError: cannot import name 'ROOT_UER' from 'config.settings' (D:\VisualStudio\Private Repository\pdl.bot Ai\config\settings.py)

The above exception was the direct cause of the following exception:

Traceback (most recent call last):
  File "D:\VisualStudio\Private Repository\pdl.bot Ai\bot\bot.py", line 47, in load_cogs
    await bot.load_extension(cog)
  File "C:\Users\User\AppData\Local\Programs\Python\Python313\Lib\site-packages\discord\ext\commands\bot.py", line 1029, in load_extension
    await self._load_from_module_spec(spec, name)
  File "C:\Users\User\AppData\Local\Programs\Python\Python313\Lib\site-packages\discord\ext\commands\bot.py", line 954, in _load_from_module_spec
    raise errors.ExtensionFailed(key, e) from e
discord.ext.commands.errors.ExtensionFailed: Extension 'commands.admin.host' raised an error: ImportError: cannot import name 'ROOT_UER' from 'config.settings' (D:\VisualStudio\Private Repository\pdl.bot Ai\config\settings.py)
[ERROR] 2025-06-12 20:44:58 - [ERROR] Une erreur s'est produite lors du démarrage de la tâche de changement de statut : 'function' object has no attribute 'is_running'
[ERROR] 2025-06-12 20:47:33 - [STATUS] Erreur lors de la définition du statut du bot par nythique (1233020939898327092) : 'Database' object has no attribute 'update_bot_status'
Traceback (most recent call last):
  File "D:\VisualStudio\Private Repository\pdl.bot Ai\commands\admin\set.py", line 110, in status
    status = db.update_bot_status(message)
             ^^^^^^^^^^^^^^^^^^^^
AttributeError: 'Database' object has no attribute 'update_bot_status'. Did you mean: 'update_bot_stats'?
[ERROR] 2025-06-12 20:47:38 - Ignoring exception in command 'status'
Traceback (most recent call last):
  File "D:\VisualStudio\Private Repository\pdl.bot Ai\commands\admin\set.py", line 110, in status
    status = db.update_bot_status(message)
             ^^^^^^^^^^^^^^^^^^^^
AttributeError: 'Database' object has no attribute 'update_bot_status'. Did you mean: 'update_bot_stats'?

During handling of the above exception, another exception occurred:

Traceback (most recent call last):
  File "C:\Users\User\AppData\Local\Programs\Python\Python313\Lib\site-packages\discord\app_commands\commands.py", line 857, in _do_call
    return await self._callback(self.binding, interaction, **params)  # type: ignore
           ^^^^^^^^^^^^^^^^^^^^^^^^^^^^^^^^^^^^^^^^^^^^^^^^^^^^^^^^^
  File "D:\VisualStudio\Private Repository\pdl.bot Ai\commands\admin\set.py", line 120, in status
    await interaction.followup.send(embed=embed, ephemeral=True)
  File "C:\Users\User\AppData\Local\Programs\Python\Python313\Lib\site-packages\discord\webhook\async_.py", line 1857, in send
    data = await adapter.execute_webhook(
           ^^^^^^^^^^^^^^^^^^^^^^^^^^^^^^
    ...<11 lines>...
    )
    ^
  File "C:\Users\User\AppData\Local\Programs\Python\Python313\Lib\site-packages\discord\webhook\async_.py", line 224, in request
    raise NotFound(response, data)
discord.errors.NotFound: 404 Not Found (error code: 10015): Unknown Webhook

The above exception was the direct cause of the following exception:

Traceback (most recent call last):
  File "C:\Users\User\AppData\Local\Programs\Python\Python313\Lib\site-packages\discord\app_commands\tree.py", line 1310, in _call
    await command._invoke_with_namespace(interaction, namespace)
  File "C:\Users\User\AppData\Local\Programs\Python\Python313\Lib\site-packages\discord\app_commands\commands.py", line 883, in _invoke_with_namespace
    return await self._do_call(interaction, transformed_values)
           ^^^^^^^^^^^^^^^^^^^^^^^^^^^^^^^^^^^^^^^^^^^^^^^^^^^^
  File "C:\Users\User\AppData\Local\Programs\Python\Python313\Lib\site-packages\discord\app_commands\commands.py", line 876, in _do_call
    raise CommandInvokeError(self, e) from e
discord.app_commands.errors.CommandInvokeError: Command 'status' raised an exception: NotFound: 404 Not Found (error code: 10015): Unknown Webhook
[ERROR] 2025-06-12 20:49:16 - [ERROR] Une erreur s'est produite lors du démarrage de la tâche de changement de statut : 'function' object has no attribute 'is_running'
[ERROR] 2025-06-12 20:50:54 - Attempting a reconnect in 0.45s
Traceback (most recent call last):
  File "C:\Users\User\AppData\Local\Programs\Python\Python313\Lib\site-packages\discord\client.py", line 704, in connect
    await self.ws.poll_event()
  File "C:\Users\User\AppData\Local\Programs\Python\Python313\Lib\site-packages\discord\gateway.py", line 627, in poll_event
    await self.received_message(msg.data)
  File "C:\Users\User\AppData\Local\Programs\Python\Python313\Lib\site-packages\discord\gateway.py", line 532, in received_message
    await self.send_as_json(beat)
  File "C:\Users\User\AppData\Local\Programs\Python\Python313\Lib\site-packages\discord\gateway.py", line 663, in send_as_json
    await self.send(utils._to_json(data))
  File "C:\Users\User\AppData\Local\Programs\Python\Python313\Lib\site-packages\discord\gateway.py", line 659, in send
    await self.socket.send_str(data)
  File "C:\Users\User\AppData\Local\Programs\Python\Python313\Lib\site-packages\aiohttp\client_ws.py", line 245, in send_str
    await self._writer.send_frame(
        data.encode("utf-8"), WSMsgType.TEXT, compress=compress
    )
  File "C:\Users\User\AppData\Local\Programs\Python\Python313\Lib\site-packages\aiohttp\_websocket\writer.py", line 125, in send_frame
    raise ClientConnectionResetError("Cannot write to closing transport")
aiohttp.client_exceptions.ClientConnectionResetError: Cannot write to closing transport
[ERROR] 2025-06-12 20:52:20 - Attempting a reconnect in 1.11s
Traceback (most recent call last):
  File "C:\Users\User\AppData\Local\Programs\Python\Python313\Lib\site-packages\discord\client.py", line 704, in connect
    await self.ws.poll_event()
  File "C:\Users\User\AppData\Local\Programs\Python\Python313\Lib\site-packages\discord\gateway.py", line 627, in poll_event
    await self.received_message(msg.data)
  File "C:\Users\User\AppData\Local\Programs\Python\Python313\Lib\site-packages\discord\gateway.py", line 532, in received_message
    await self.send_as_json(beat)
  File "C:\Users\User\AppData\Local\Programs\Python\Python313\Lib\site-packages\discord\gateway.py", line 663, in send_as_json
    await self.send(utils._to_json(data))
  File "C:\Users\User\AppData\Local\Programs\Python\Python313\Lib\site-packages\discord\gateway.py", line 659, in send
    await self.socket.send_str(data)
  File "C:\Users\User\AppData\Local\Programs\Python\Python313\Lib\site-packages\aiohttp\client_ws.py", line 245, in send_str
    await self._writer.send_frame(
        data.encode("utf-8"), WSMsgType.TEXT, compress=compress
    )
  File "C:\Users\User\AppData\Local\Programs\Python\Python313\Lib\site-packages\aiohttp\_websocket\writer.py", line 125, in send_frame
    raise ClientConnectionResetError("Cannot write to closing transport")
aiohttp.client_exceptions.ClientConnectionResetError: Cannot write to closing transport
[ERROR] 2025-06-12 20:54:17 - Attempting a reconnect in 7.17s
Traceback (most recent call last):
  File "C:\Users\User\AppData\Local\Programs\Python\Python313\Lib\site-packages\discord\client.py", line 704, in connect
    await self.ws.poll_event()
  File "C:\Users\User\AppData\Local\Programs\Python\Python313\Lib\site-packages\discord\gateway.py", line 627, in poll_event
    await self.received_message(msg.data)
  File "C:\Users\User\AppData\Local\Programs\Python\Python313\Lib\site-packages\discord\gateway.py", line 532, in received_message
    await self.send_as_json(beat)
  File "C:\Users\User\AppData\Local\Programs\Python\Python313\Lib\site-packages\discord\gateway.py", line 663, in send_as_json
    await self.send(utils._to_json(data))
  File "C:\Users\User\AppData\Local\Programs\Python\Python313\Lib\site-packages\discord\gateway.py", line 659, in send
    await self.socket.send_str(data)
  File "C:\Users\User\AppData\Local\Programs\Python\Python313\Lib\site-packages\aiohttp\client_ws.py", line 245, in send_str
    await self._writer.send_frame(
        data.encode("utf-8"), WSMsgType.TEXT, compress=compress
    )
  File "C:\Users\User\AppData\Local\Programs\Python\Python313\Lib\site-packages\aiohttp\_websocket\writer.py", line 125, in send_frame
    raise ClientConnectionResetError("Cannot write to closing transport")
aiohttp.client_exceptions.ClientConnectionResetError: Cannot write to closing transport
[ERROR] 2025-06-12 20:54:18 - [PING] Erreur lors de l'exécution de la commande ping : 404 Not Found (error code: 10062): Unknown interaction
Traceback (most recent call last):
  File "D:\VisualStudio\Private Repository\pdl.bot Ai\commands\public\ping.py", line 46, in ping
    await interaction.response.send_message(embed=embed, ephemeral=False)
  File "C:\Users\User\AppData\Local\Programs\Python\Python313\Lib\site-packages\discord\interactions.py", line 1004, in send_message
    response = await adapter.create_interaction_response(
               ^^^^^^^^^^^^^^^^^^^^^^^^^^^^^^^^^^^^^^^^^^
    ...<6 lines>...
    )
    ^
  File "C:\Users\User\AppData\Local\Programs\Python\Python313\Lib\site-packages\discord\webhook\async_.py", line 224, in request
    raise NotFound(response, data)
discord.errors.NotFound: 404 Not Found (error code: 10062): Unknown interaction
[ERROR] 2025-06-12 20:54:47 - Ignoring exception in command 'ping'
Traceback (most recent call last):
  File "D:\VisualStudio\Private Repository\pdl.bot Ai\commands\public\ping.py", line 46, in ping
    await interaction.response.send_message(embed=embed, ephemeral=False)
  File "C:\Users\User\AppData\Local\Programs\Python\Python313\Lib\site-packages\discord\interactions.py", line 1004, in send_message
    response = await adapter.create_interaction_response(
               ^^^^^^^^^^^^^^^^^^^^^^^^^^^^^^^^^^^^^^^^^^
    ...<6 lines>...
    )
    ^
  File "C:\Users\User\AppData\Local\Programs\Python\Python313\Lib\site-packages\discord\webhook\async_.py", line 224, in request
    raise NotFound(response, data)
discord.errors.NotFound: 404 Not Found (error code: 10062): Unknown interaction

During handling of the above exception, another exception occurred:

Traceback (most recent call last):
  File "C:\Users\User\AppData\Local\Programs\Python\Python313\Lib\site-packages\discord\app_commands\commands.py", line 857, in _do_call
    return await self._callback(self.binding, interaction, **params)  # type: ignore
           ^^^^^^^^^^^^^^^^^^^^^^^^^^^^^^^^^^^^^^^^^^^^^^^^^^^^^^^^^
  File "D:\VisualStudio\Private Repository\pdl.bot Ai\commands\public\ping.py", line 56, in ping
    await interaction.response.send_message(embed=error_embed, ephemeral=True)
  File "C:\Users\User\AppData\Local\Programs\Python\Python313\Lib\site-packages\discord\interactions.py", line 1004, in send_message
    response = await adapter.create_interaction_response(
               ^^^^^^^^^^^^^^^^^^^^^^^^^^^^^^^^^^^^^^^^^^
    ...<6 lines>...
    )
    ^
  File "C:\Users\User\AppData\Local\Programs\Python\Python313\Lib\site-packages\discord\webhook\async_.py", line 224, in request
    raise NotFound(response, data)
discord.errors.NotFound: 404 Not Found (error code: 10062): Unknown interaction

The above exception was the direct cause of the following exception:

Traceback (most recent call last):
  File "C:\Users\User\AppData\Local\Programs\Python\Python313\Lib\site-packages\discord\app_commands\tree.py", line 1310, in _call
    await command._invoke_with_namespace(interaction, namespace)
  File "C:\Users\User\AppData\Local\Programs\Python\Python313\Lib\site-packages\discord\app_commands\commands.py", line 883, in _invoke_with_namespace
    return await self._do_call(interaction, transformed_values)
           ^^^^^^^^^^^^^^^^^^^^^^^^^^^^^^^^^^^^^^^^^^^^^^^^^^^^
  File "C:\Users\User\AppData\Local\Programs\Python\Python313\Lib\site-packages\discord\app_commands\commands.py", line 876, in _do_call
    raise CommandInvokeError(self, e) from e
discord.app_commands.errors.CommandInvokeError: Command 'ping' raised an exception: NotFound: 404 Not Found (error code: 10062): Unknown interaction
[ERROR] 2025-06-12 20:54:47 - [HOST] Erreur lors de l'affichage de l'hôte pour nythique (1233020939898327092): name 'bot_user' is not defined
Traceback (most recent call last):
  File "D:\VisualStudio\Private Repository\pdl.bot Ai\commands\admin\host.py", line 54, in host
    icon_url=bot_user.display_avatar.url
             ^^^^^^^^
NameError: name 'bot_user' is not defined
[ERROR] 2025-06-12 20:54:47 - Ignoring exception in command 'host'
Traceback (most recent call last):
  File "D:\VisualStudio\Private Repository\pdl.bot Ai\commands\admin\host.py", line 54, in host
    icon_url=bot_user.display_avatar.url
             ^^^^^^^^
NameError: name 'bot_user' is not defined

During handling of the above exception, another exception occurred:

Traceback (most recent call last):
  File "C:\Users\User\AppData\Local\Programs\Python\Python313\Lib\site-packages\discord\app_commands\commands.py", line 857, in _do_call
    return await self._callback(self.binding, interaction, **params)  # type: ignore
           ^^^^^^^^^^^^^^^^^^^^^^^^^^^^^^^^^^^^^^^^^^^^^^^^^^^^^^^^^
  File "D:\VisualStudio\Private Repository\pdl.bot Ai\commands\admin\host.py", line 65, in host
    await interaction.response.send_message(embed=error_embed, ephemeral=True)
  File "C:\Users\User\AppData\Local\Programs\Python\Python313\Lib\site-packages\discord\interactions.py", line 1004, in send_message
    response = await adapter.create_interaction_response(
               ^^^^^^^^^^^^^^^^^^^^^^^^^^^^^^^^^^^^^^^^^^
    ...<6 lines>...
    )
    ^
  File "C:\Users\User\AppData\Local\Programs\Python\Python313\Lib\site-packages\discord\webhook\async_.py", line 224, in request
    raise NotFound(response, data)
discord.errors.NotFound: 404 Not Found (error code: 10062): Unknown interaction

The above exception was the direct cause of the following exception:

Traceback (most recent call last):
  File "C:\Users\User\AppData\Local\Programs\Python\Python313\Lib\site-packages\discord\app_commands\tree.py", line 1310, in _call
    await command._invoke_with_namespace(interaction, namespace)
  File "C:\Users\User\AppData\Local\Programs\Python\Python313\Lib\site-packages\discord\app_commands\commands.py", line 883, in _invoke_with_namespace
    return await self._do_call(interaction, transformed_values)
           ^^^^^^^^^^^^^^^^^^^^^^^^^^^^^^^^^^^^^^^^^^^^^^^^^^^^
  File "C:\Users\User\AppData\Local\Programs\Python\Python313\Lib\site-packages\discord\app_commands\commands.py", line 876, in _do_call
    raise CommandInvokeError(self, e) from e
discord.app_commands.errors.CommandInvokeError: Command 'host' raised an exception: NotFound: 404 Not Found (error code: 10062): Unknown interaction
